[hnbaixmon.kdc.capitalone.com]: UNREACHABLE! => {"changed": false, "msg": "ERROR! SSH encountered an unknown error during the connection. We recommend you re-run the command using -vvvv, which will enable SSH debugging output to help diagnose the issue", "unreachable": true}[0m
[normandy.kdc.capitalone.com]: UNREACHABLE! => {"changed": false, "msg": "ERROR! SSH encountered an unknown error during the connection. We recommend you re-run the command using -vvvv, which will enable SSH debugging output to help diagnose the issue", "unreachable": true}[0m
[sd2n2v4.kdc.capitalone.com]: FAILED! => {"changed": false, "failed": true, "module_stderr": "", "module_stdout": "3431.1 Security error, please see your administrator.rnpbrun6.2.0-09[16643]: Could not connect to run host sd2n2v4.kdc.capitalone.comn", "msg": "MODULE FAILURE", "parsed": false}[0m
[icebird.kdc.capitalone.com]: FAILED! => {"changed": false, "failed": true, "module_stderr": "", "module_stdout": " File "/home/aaa/.ansible/tmp/ansible-tmp-1457021533.51-116198397865129/setup", line 360rn return dict((_convert(k), _convert(v)) for k, v in node.items())rn ^rnSyntaxError: invalid syntaxrn", "msg": "MODULE FAILURE", "parsed": false}[0m
[aquifer664.kdc.capitalone.com][0m
[cruise.kdc.capitalone.com]: FAILED! => {"changed": false, "failed": true, "module_stderr": "", "module_stdout": "ERROR:root:code for hash md5 was not found.rnTraceback (most recent call last):rn File "/opt/freeware/lib/python2.7/hashlib.py", line 139, in <module>rn globals()[__func_name] = __get_hash(__func_name)rn File "/opt/freeware/lib/python2.7/hashlib.py", line 91, in __get_builtin_constructorrn raise ValueError('unsupported hash type ' + name)rnValueError: unsupported hash type md5rnERROR:root:code for hash sha1 was not found.rnTraceback (most recent call last):rn File "/opt/freeware/lib/python2.7/hashlib.py", line 139, in <module>rn globals()[__func_name] = __get_hash(__func_name)rn File "/opt/freeware/lib/python2.7/hashlib.py", line 91, in __get_builtin_constructorrn raise ValueError('unsupported hash type ' + name)rnValueError: unsupported hash type sha1rnERROR:root:code for hash sha224 was not found.rnTraceback (most recent call last):rn File "/opt/freeware/lib/python2.7/hashlib.py", line 139, in <module>rn globals()[__func_name] = __get_hash(__func_name)rn File "/opt/freeware/lib/python2.7/hashlib.py", line 91, in __get_builtin_constructorrn raise ValueError('unsupported hash type ' + name)rnValueError: unsupported hash type sha224rnERROR:root:code for hash sha256 was not found.rnTraceback (most recent call last):rn File "/opt/freeware/lib/python2.7/hashlib.py", line 139, in <module>rn globals()[__func_name] = __get_hash(__func_name)rn File "/opt/freeware/lib/python2.7/hashlib.py", line 91, in __get_builtin_constructorrn raise ValueError('unsupported hash type ' + name)rnValueError: unsupported hash type sha256rnERROR:root:code for hash sha384 was not found.rnTraceback (most recent call last):rn File "/opt/freeware/lib/python2.7/hashlib.py", line 139, in <module>rn globals()[__func_name] = __get_hash(__func_name)rn File "/opt/freeware/lib/python2.7/hashlib.py", line 91, in __get_builtin_constructorrn raise ValueError('unsupported hash type ' + name)rnValueError: unsupported hash type sha384rnERROR:root:code for hash sha512 was not found.rnTraceback (most recent call last):rn File "/opt/freeware/lib/python2.7/hashlib.py", line 139, in <module>rn globals()[__func_name] = __get_hash(__func_name)rn File "/opt/freeware/lib/python2.7/hashlib.py", line 91, in __get_builtin_constructorrn raise ValueError('unsupported hash type ' + name)rnValueError: unsupported hash type sha512rnTraceback (most recent call last):rn File "/home/aaa/.ansible/tmp/ansible-tmp-1457021534.9-116818433545557/setup", line 320, in <module>rn AVAILABLE_HASH_ALGORITHMS[algorithm] = getattr(hashlib, algorithm)rnAttributeError: 'module' object has no attribute 'md5'rn", "msg": "MODULE FAILURE", "parsed": false}[0m
[hurley.kdc.capitalone.com][0m
[janie.kdc.capitalone.com]: UNREACHABLE! => {"changed": false, "msg": "ERROR! SSH encountered an unknown error during the connection. We recommend you re-run the command using -vvvv, which will enable SSH debugging output to help diagnose the issue", "unreachable": true}[0m
[nigel2.kdc.capitalone.com]: FAILED! => {"changed": false, "failed": true, "module_stderr": "", "module_stdout": "3431.1 Security error, please see your administrator.rnpbrun6.2.0-09[8655]: Could not connect to run host nigel2.kdc.capitalone.comn", "msg": "MODULE FAILURE", "parsed": false}[0m
[kdcnim01.kdc.capitalone.com]: FAILED! => {"changed": false, "failed": true, "module_stderr": "", "module_stdout": " File "/home/aaa/.ansible/tmp/ansible-tmp-1457021536.87-273285931609287/setup", line 360rn return dict((_convert(k), _convert(v)) for k, v in node.items())rn ^rnSyntaxError: invalid syntaxrn", "msg": "MODULE FAILURE", "parsed": false}[0m
[stealth.kdc.capitalone.com]: UNREACHABLE! => {"changed": false, "msg": "ERROR! SSH encountered an unknown error during the connection. We recommend you re-run the command using -vvvv, which will enable SSH debugging output to help diagnose the issue", "unreachable": true}[0m
[plmcduck.kdc.capitalone.com]: UNREACHABLE! => {"changed": false, "msg": "ERROR! SSH encountered an unknown error during the connection. We recommend you re-run the command using -vvvv, which will enable SSH debugging output to help diagnose the issue", "unreachable": true}[0m
[pdcjumpstart.kdc.capitalone.com]: UNREACHABLE! => {"changed": false, "msg": "ERROR! SSH encountered an unknown error during the connection. We recommend you re-run the command using -vvvv, which will enable SSH debugging output to help diagnose the issue", "unreachable": true}[0m
[devcaps01.kdc.capitalone.com]: UNREACHABLE! => {"changed": false, "msg": "ERROR! SSH encountered an unknown error during the connection. We recommend you re-run the command using -vvvv, which will enable SSH debugging output to help diagnose the issue", "unreachable": true}[0m
[radius.kdc.capitalone.com][0m
[utah.kdc.capitalone.com]: UNREACHABLE! => {"changed": false, "msg": "ERROR! SSH encountered an unknown error during the connection. We recommend you re-run the command using -vvvv, which will enable SSH debugging output to help diagnose the issue", "unreachable": true}[0m
[kdcinfo.kdc.capitalone.com]: FAILED! => {"changed": false, "failed": true, "module_stderr": "", "module_stdout": "rn ... pbrun is depreciated .. you should be using the new Centrify tool - 'dzdo' instead . rnrn ... Syntax for dzdo is 'dzdo -u <Effective.user> <command>' rnrn ... Example:- 'dzdo -u ddebatch cat /prod/users/ddebatch/file1' rnrn ... to check what elevated commands you have access to, execute 'dzdo -l' rnrn ... For more information, please visit the pulse page -> https://pulse.kdc.capitalone.com/docs/DOC-129371 rnrn ... redirecting to dzdo ... rnrn ... executing /usr/bin/dzdo -u root -b -l -u root /usr/bin/python /home/aaa/.ansible/tmp/ansible-tmp-1457021542.34-227265917948418/setup rndzdo: you may not specify both the `-l' option and [command]rnusage: dzdo -K | -k | -Vrnusage: dzdo -v [-AknS] [-g groupname|#gid] [-p prompt] [-u username|#uid]rnusage: dzdo -l[l] [-AknS] [-g groupname|#gid] [-p prompt] [-u username|#uid]rn [command]rnusage: dzdo [-AbHknPS] [-C num] [-g groupname|#gid] [-p prompt] [-urn username|#uid] [VAR=value] [-i|-s] [<command>]rnusage: dzdo -e [-AknS] [-C num] [-g groupname|#gid] [-p prompt] [-urn username|#uid] file ...rnusage: dzdo -h [user@]<host> [-W,ssh-option] <arguments>rnusage: dzdo --helprn", "msg": "MODULE FAILURE", "parsed": false}[0m
[drdns1.kdc.capitalone.com]: UNREACHABLE! => {"changed": false, "msg": "ERROR! SSH encountered an unknown error during the connection. We recommend you re-run the command using -vvvv, which will enable SSH debugging output to help diagnose the issue", "unreachable": true}[0m
[bourne.kdc.capitalone.com]: UNREACHABLE! => {"changed": false, "msg": "ERROR! SSH encountered an unknown error during the connection. We recommend you re-run the command using -vvvv, which will enable SSH debugging output to help diagnose the issue", "unreachable": true}[0m
[drdns2.kdc.capitalone.com]: UNREACHABLE! => {"changed": false, "msg": "ERROR! SSH encountered an unknown error during the connection. We recommend you re-run the command using -vvvv, which will enable SSH debugging output to help diagnose the issue", "unreachable": true}[0m

